<?xml version="1.0" encoding="utf-8"?>
<mujoco>
	<compiler angle="radian" coordinate="local" meshdir="../stls/fetch" texturedir="../textures"></compiler>
	<option timestep="0.002">
		<flag warmstart="enable"></flag>
	</option>

	<include file="shared.xml"></include>

	<worldbody>
		<geom name="floor0" pos="0.8 0.75 0" size="0.85 0.70 1" type="plane" condim="3" material="floor_mat"></geom>
		<body name="floor0" pos="0.8 0.75 0">
			<site name="target0" pos="0.7 0.0 0.4" size="0.02 0.02 0.02" rgba="1 0 0 1" type="sphere"></site>
		</body>

		<include file="robot.xml"></include>

		<body pos="1.3 0.75 0.2" name="table0">
			<geom size="0.30 0.40 0.2" type="box" mass="2000" material="table_mat"></geom>
		</body>

		<!--geom name="wall0" pos="1.25 0.975 0.45" size="0.02 0.125 0.05" type="box" condim="3" mass="100" material="table_mat" rgba="0.93 0.93 0.93 0.5"></geom>
        <geom name="wall1" pos="1.25 0.525 0.45" size="0.02 0.125 0.05" type="box" condim="3" mass="100" material="table_mat" rgba="0.93 0.93 0.93 0.5"></geom!-->
        <geom name="wall0" pos="1.1 0.58 0.45" size="0.1 0.02 0.05" type="box" condim="3" mass="100" material="table_mat" rgba="0.93 0.93 0.93 0.5"></geom>
        <geom name="wall1" pos="1.5 0.58 0.45" size="0.1 0.02 0.05" type="box" condim="3" mass="100" material="table_mat" rgba="0.93 0.93 0.93 0.5"></geom>
        <geom name="wall2" pos="1.1 0.92 0.45" size="0.1 0.02 0.05" type="box" condim="3" mass="100" material="table_mat" rgba="0.93 0.93 0.93 0.5"></geom>
        <geom name="wall3" pos="1.5 0.92 0.45" size="0.1 0.02 0.05" type="box" condim="3" mass="100" material="table_mat" rgba="0.93 0.93 0.93 0.5"></geom>

		<body name="object0" pos="0 0 0.425">
			<!--joint name="object0:joint" type="free" damping="0.01"></joint!-->
			<joint axis="1 0 0" name="object0:slidex" type="slide" damping="0.01"></joint>
			<joint axis="0 1 0" name="object0:slidey" type="slide" damping="0.01"></joint>
			<geom size="0.025 0.025 0.025" type="box" condim="3" name="object0" material="block_mat" mass="2"></geom>
			<!--geom size="0.025 0.025 0.025" type="sphere" condim="6" name="object0" material="block_mat" mass="2"></geom!-->
			<site name="object0" pos="0 0 0" size="0.02 0.02 0.02" rgba="1 0 0 1" type="sphere"></site>
		</body>

		<body name="object1" pos="0 0 0.43">
			<joint name="object1:joint" type="free" damping="0.01"></joint>
			<!--joint axis="1 0 0" name="object1:slidex" type="slide" damping="0.01"></joint>
			<joint axis="0 1 0" name="object1:slidey" type="slide" damping="0.01"></joint!-->
			<geom size="0.13 0.03 0.03" type="box" condim="3" name="object1" material="stick_mat" mass="2000" friction="1 0.005 0.0001"></geom>
			<site name="object1" pos="0 0 0" size="0.02 0.02 0.02" rgba="0.5 0.2 0 0" type="sphere"></site>
		</body>
        <body name="object2" pos="0 0 0.43">
			<joint name="object2:joint" type="free" damping="0.01"></joint>
			<!--joint axis="1 0 0" name="object2:slidex" type="slide" damping="0.01"></joint>
			<joint axis="0 1 0" name="object2:slidey" type="slide" damping="0.01"></joint!-->
			<geom size="0.13 0.03 0.03" type="box" condim="3" name="object2" material="stick_mat" rgba="1 0 1 0.5" mass="2000" friction="1 0.005 0.0001"></geom>
			<site name="object2" pos="0 0 0" size="0.02 0.02 0.02" rgba="0.5 0.2 0 0" type="sphere"></site>
		</body>

		<light directional="true" ambient="0.2 0.2 0.2" diffuse="0.8 0.8 0.8" specular="0.3 0.3 0.3" castshadow="false" pos="0 0 4" dir="0 0 -1" name="light0"></light>
	</worldbody>

	<actuator></actuator>
</mujoco>
